Workbook

Sheet Summary
A1: Sub Sheet | B1: Playbook | C1: Total | D1: Head Pass | E1: Head Fail | F1: Head Pass % | G1: Head Fail % | H1: Sub Pass | I1: Sub Fail | J1: Sub Pass % | K1: Sub Fail %
A2: AG_change-account | B2: Agent | C2: =D2+E2 -> 60 | D2: =COUNTIF('AG_change-account'!D2:D61,TRUE()) -> 60 | E2: =COUNTIF('AG_change-account'!D2:D61,FALSE()) -> 0 | F2: =IF($C2=0,0,D2/$C2) -> 1 | G2: =IF($C2=0,0,E2/$C2) -> 0 | H2: =COUNTIF('AG_change-account'!G2:G61,TRUE()) -> 60 | I2: =COUNTIF('AG_change-account'!G2:G61,FALSE()) -> 0 | J2: =IF($C2=0,0,H2/$C2) -> 1 | K2: =IF($C2=0,0,I2/$C2) -> 0
A3: AG_change-address | B3: Agent | C3: =D3+E3 -> 60 | D3: =COUNTIF('AG_change-address'!D2:D61,TRUE()) -> 60 | E3: =COUNTIF('AG_change-address'!D2:D61,FALSE()) -> 0 | F3: =IF($C3=0,0,D3/$C3) -> 1 | G3: =IF($C3=0,0,E3/$C3) -> 0 | H3: =COUNTIF('AG_change-address'!G2:G61,TRUE()) -> 60 | I3: =COUNTIF('AG_change-address'!G2:G61,FALSE()) -> 0 | J3: =IF($C3=0,0,H3/$C3) -> 1 | K3: =IF($C3=0,0,I3/$C3) -> 0
A4: AG_change-admin | B4: Agent | C4: =D4+E4 -> 60 | D4: =COUNTIF('AG_change-admin'!D2:D61,TRUE()) -> 60 | E4: =COUNTIF('AG_change-admin'!D2:D61,FALSE()) -> 0 | F4: =IF($C4=0,0,D4/$C4) -> 1 | G4: =IF($C4=0,0,E4/$C4) -> 0 | H4: =COUNTIF('AG_change-admin'!G2:G61,TRUE()) -> 60 | I4: =COUNTIF('AG_change-admin'!G2:G61,FALSE()) -> 0 | J4: =IF($C4=0,0,H4/$C4) -> 1 | K4: =IF($C4=0,0,I4/$C4) -> 0
A5: AG_change-dependent_info | B5: Agent | C5: =D5+E5 -> 60 | D5: =COUNTIF('AG_change-dependent_info'!D2:D61,TRUE()) -> 60 | E5: =COUNTIF('AG_change-dependent_info'!D2:D61,FALSE()) -> 0 | F5: =IF($C5=0,0,D5/$C5) -> 1 | G5: =IF($C5=0,0,E5/$C5) -> 0 | H5: =COUNTIF('AG_change-dependent_info'!G2:G61,TRUE()) -> 60 | I5: =COUNTIF('AG_change-dependent_info'!G2:G61,FALSE()) -> 0 | J5: =IF($C5=0,0,H5/$C5) -> 1 | K5: =IF($C5=0,0,I5/$C5) -> 0
A6: AG_change-group_info | B6: Agent | C6: =D6+E6 -> 60 | D6: =COUNTIF('AG_change-group_info'!D2:D61,TRUE()) -> 59 | E6: =COUNTIF('AG_change-group_info'!D2:D61,FALSE()) -> 1 | F6: =IF($C6=0,0,D6/$C6) -> 0.98333333 | G6: =IF($C6=0,0,E6/$C6) -> 0.016666667 | H6: =COUNTIF('AG_change-group_info'!G2:G61,TRUE()) -> 59 | I6: =COUNTIF('AG_change-group_info'!G2:G61,FALSE()) -> 1 | J6: =IF($C6=0,0,H6/$C6) -> 0.98333333 | K6: =IF($C6=0,0,I6/$C6) -> 0.016666667
A7: AG_change-provider | B7: Agent | C7: =D7+E7 -> 60 | D7: =COUNTIF('AG_change-provider'!D2:D61,TRUE()) -> 60 | E7: =COUNTIF('AG_change-provider'!D2:D61,FALSE()) -> 0 | F7: =IF($C7=0,0,D7/$C7) -> 1 | G7: =IF($C7=0,0,E7/$C7) -> 0 | H7: =COUNTIF('AG_change-provider'!G2:G61,TRUE()) -> 60 | I7: =COUNTIF('AG_change-provider'!G2:G61,FALSE()) -> 0 | J7: =IF($C7=0,0,H7/$C7) -> 1 | K7: =IF($C7=0,0,I7/$C7) -> 0
A8: AG_find-provider | B8: Agent | C8: =D8+E8 -> 60 | D8: =COUNTIF('AG_find-provider'!D2:D61,TRUE()) -> 60 | E8: =COUNTIF('AG_find-provider'!D2:D61,FALSE()) -> 0 | F8: =IF($C8=0,0,D8/$C8) -> 1 | G8: =IF($C8=0,0,E8/$C8) -> 0 | H8: =COUNTIF('AG_find-provider'!G2:G61,TRUE()) -> 60 | I8: =COUNTIF('AG_find-provider'!G2:G61,FALSE()) -> 0 | J8: =IF($C8=0,0,H8/$C8) -> 1 | K8: =IF($C8=0,0,I8/$C8) -> 0
A9: AG_inquire-account_status | B9: Agent | C9: =D9+E9 -> 60 | D9: =COUNTIF('AG_inquire-account_status'!D2:D61,TRUE()) -> 60 | E9: =COUNTIF('AG_inquire-account_status'!D2:D61,FALSE()) -> 0 | F9: =IF($C9=0,0,D9/$C9) -> 1 | G9: =IF($C9=0,0,E9/$C9) -> 0 | H9: =COUNTIF('AG_inquire-account_status'!G2:G61,TRUE()) -> 60 | I9: =COUNTIF('AG_inquire-account_status'!G2:G61,FALSE()) -> 0 | J9: =IF($C9=0,0,H9/$C9) -> 1 | K9: =IF($C9=0,0,I9/$C9) -> 0
A10: AG_report-problem_account | B10: Agent | C10: =D10+E10 -> 60 | D10: =COUNTIF('AG_report-problem_account'!D2:D61,TRUE()) -> 60 | E10: =COUNTIF('AG_report-problem_account'!D2:D61,FALSE()) -> 0 | F10: =IF($C10=0,0,D10/$C10) -> 1 | G10: =IF($C10=0,0,E10/$C10) -> 0 | H10: =COUNTIF('AG_report-problem_account'!G2:G61,TRUE()) -> 60 | I10: =COUNTIF('AG_report-problem_account'!G2:G61,FALSE()) -> 0 | J10: =IF($C10=0,0,H10/$C10) -> 1 | K10: =IF($C10=0,0,I10/$C10) -> 0
A11: AG_request-address | B11: Agent | C11: =D11+E11 -> 60 | D11: =COUNTIF('AG_request-address'!D2:D61,TRUE()) -> 57 | E11: =COUNTIF('AG_request-address'!D2:D61,FALSE()) -> 3 | F11: =IF($C11=0,0,D11/$C11) -> 0.95 | G11: =IF($C11=0,0,E11/$C11) -> 0.05 | H11: =COUNTIF('AG_request-address'!G2:G61,TRUE()) -> 56 | I11: =COUNTIF('AG_request-address'!G2:G61,FALSE()) -> 4 | J11: =IF($C11=0,0,H11/$C11) -> 0.93333333 | K11: =IF($C11=0,0,I11/$C11) -> 0.066666667
A12: AG_request-agent | B12: Agent | C12: =D12+E12 -> 60 | D12: =COUNTIF('AG_request-agent'!D2:D61,TRUE()) -> 59 | E12: =COUNTIF('AG_request-agent'!D2:D61,FALSE()) -> 1 | F12: =IF($C12=0,0,D12/$C12) -> 0.98333333 | G12: =IF($C12=0,0,E12/$C12) -> 0.016666667 | H12: =COUNTIF('AG_request-agent'!G2:G61,TRUE()) -> 59 | I12: =COUNTIF('AG_request-agent'!G2:G61,FALSE()) -> 1 | J12: =IF($C12=0,0,H12/$C12) -> 0.98333333 | K12: =IF($C12=0,0,I12/$C12) -> 0.016666667
A13: AG_request-agent_specific | B13: Agent | C13: =D13+E13 -> 60 | D13: =COUNTIF('AG_request-agent_specific'!D2:D61,TRUE()) -> 59 | E13: =COUNTIF('AG_request-agent_specific'!D2:D61,FALSE()) -> 1 | F13: =IF($C13=0,0,D13/$C13) -> 0.98333333 | G13: =IF($C13=0,0,E13/$C13) -> 0.016666667 | H13: =COUNTIF('AG_request-agent_specific'!G2:G61,TRUE()) -> 59 | I13: =COUNTIF('AG_request-agent_specific'!G2:G61,FALSE()) -> 1 | J13: =IF($C13=0,0,H13/$C13) -> 0.98333333 | K13: =IF($C13=0,0,I13/$C13) -> 0.016666667
A14: AG_request-contact_info | B14: Agent | C14: =D14+E14 -> 60 | D14: =COUNTIF('AG_request-contact_info'!D2:D61,TRUE()) -> 58 | E14: =COUNTIF('AG_request-contact_info'!D2:D61,FALSE()) -> 2 | F14: =IF($C14=0,0,D14/$C14) -> 0.96666667 | G14: =IF($C14=0,0,E14/$C14) -> 0.033333333 | H14: =COUNTIF('AG_request-contact_info'!G2:G61,TRUE()) -> 58 | I14: =COUNTIF('AG_request-contact_info'!G2:G61,FALSE()) -> 2 | J14: =IF($C14=0,0,H14/$C14) -> 0.96666667 | K14: =IF($C14=0,0,I14/$C14) -> 0.033333333
A15: AG_respond-letter | B15: Agent | C15: =D15+E15 -> 60 | D15: =COUNTIF('AG_respond-letter'!D2:D61,TRUE()) -> 60 | E15: =COUNTIF('AG_respond-letter'!D2:D61,FALSE()) -> 0 | F15: =IF($C15=0,0,D15/$C15) -> 1 | G15: =IF($C15=0,0,E15/$C15) -> 0 | H15: =COUNTIF('AG_respond-letter'!G2:G61,TRUE()) -> 60 | I15: =COUNTIF('AG_respond-letter'!G2:G61,FALSE()) -> 0 | J15: =IF($C15=0,0,H15/$C15) -> 1 | K15: =IF($C15=0,0,I15/$C15) -> 0
A16: AG_return-call | B16: Agent | C16: =D16+E16 -> 60 | D16: =COUNTIF('AG_return-call'!D2:D61,TRUE()) -> 60 | E16: =COUNTIF('AG_return-call'!D2:D61,FALSE()) -> 0 | F16: =IF($C16=0,0,D16/$C16) -> 1 | G16: =IF($C16=0,0,E16/$C16) -> 0 | H16: =COUNTIF('AG_return-call'!G2:G61,TRUE()) -> 60 | I16: =COUNTIF('AG_return-call'!G2:G61,FALSE()) -> 0 | J16: =IF($C16=0,0,H16/$C16) -> 1 | K16: =IF($C16=0,0,I16/$C16) -> 0
A17: AG_say-something_else | B17: Agent | C17: =D17+E17 -> 60 | D17: =COUNTIF('AG_say-something_else'!D2:D61,TRUE()) -> 59 | E17: =COUNTIF('AG_say-something_else'!D2:D61,FALSE()) -> 1 | F17: =IF($C17=0,0,D17/$C17) -> 0.98333333 | G17: =IF($C17=0,0,E17/$C17) -> 0.016666667 | H17: =COUNTIF('AG_say-something_else'!G2:G61,TRUE()) -> 59 | I17: =COUNTIF('AG_say-something_else'!G2:G61,FALSE()) -> 1 | J17: =IF($C17=0,0,H17/$C17) -> 0.98333333 | K17: =IF($C17=0,0,I17/$C17) -> 0.016666667
A18: AG_terminate-employee | B18: Agent | C18: =D18+E18 -> 60 | D18: =COUNTIF('AG_terminate-employee'!D2:D61,TRUE()) -> 59 | E18: =COUNTIF('AG_terminate-employee'!D2:D61,FALSE()) -> 1 | F18: =IF($C18=0,0,D18/$C18) -> 0.98333333 | G18: =IF($C18=0,0,E18/$C18) -> 0.016666667 | H18: =COUNTIF('AG_terminate-employee'!G2:G61,TRUE()) -> 59 | I18: =COUNTIF('AG_terminate-employee'!G2:G61,FALSE()) -> 1 | J18: =IF($C18=0,0,H18/$C18) -> 0.98333333 | K18: =IF($C18=0,0,I18/$C18) -> 0.016666667
A19: AG_vague-account | B19: Agent | C19: =D19+E19 -> 60 | D19: =COUNTIF('AG_vague-account'!D2:D61,TRUE()) -> 58 | E19: =COUNTIF('AG_vague-account'!D2:D61,FALSE()) -> 2 | F19: =IF($C19=0,0,D19/$C19) -> 0.96666667 | G19: =IF($C19=0,0,E19/$C19) -> 0.033333333 | H19: =COUNTIF('AG_vague-account'!G2:G61,TRUE()) -> 58 | I19: =COUNTIF('AG_vague-account'!G2:G61,FALSE()) -> 2 | J19: =IF($C19=0,0,H19/$C19) -> 0.96666667 | K19: =IF($C19=0,0,I19/$C19) -> 0.033333333
A20: AG_vague-address | B20: Agent | C20: =D20+E20 -> 60 | D20: =COUNTIF('AG_vague-address'!D2:D61,TRUE()) -> 59 | E20: =COUNTIF('AG_vague-address'!D2:D61,FALSE()) -> 1 | F20: =IF($C20=0,0,D20/$C20) -> 0.98333333 | G20: =IF($C20=0,0,E20/$C20) -> 0.016666667 | H20: =COUNTIF('AG_vague-address'!G2:G61,TRUE()) -> 59 | I20: =COUNTIF('AG_vague-address'!G2:G61,FALSE()) -> 1 | J20: =IF($C20=0,0,H20/$C20) -> 0.98333333 | K20: =IF($C20=0,0,I20/$C20) -> 0.016666667
A21: AG_vague-appointment | B21: Agent | C21: =D21+E21 -> 60 | D21: =COUNTIF('AG_vague-appointment'!D2:D61,TRUE()) -> 60 | E21: =COUNTIF('AG_vague-appointment'!D2:D61,FALSE()) -> 0 | F21: =IF($C21=0,0,D21/$C21) -> 1 | G21: =IF($C21=0,0,E21/$C21) -> 0 | H21: =COUNTIF('AG_vague-appointment'!G2:G61,TRUE()) -> 60 | I21: =COUNTIF('AG_vague-appointment'!G2:G61,FALSE()) -> 0 | J21: =IF($C21=0,0,H21/$C21) -> 1 | K21: =IF($C21=0,0,I21/$C21) -> 0
A22: AG_vague-disability | B22: Agent | C22: =D22+E22 -> 60 | D22: =COUNTIF('AG_vague-disability'!D2:D61,TRUE()) -> 60 | E22: =COUNTIF('AG_vague-disability'!D2:D61,FALSE()) -> 0 | F22: =IF($C22=0,0,D22/$C22) -> 1 | G22: =IF($C22=0,0,E22/$C22) -> 0 | H22: =COUNTIF('AG_vague-disability'!G2:G61,TRUE()) -> 60 | I22: =COUNTIF('AG_vague-disability'!G2:G61,FALSE()) -> 0 | J22: =IF($C22=0,0,H22/$C22) -> 1 | K22: =IF($C22=0,0,I22/$C22) -> 0
A23: AG_vague-employee | B23: Agent | C23: =D23+E23 -> 60 | D23: =COUNTIF('AG_vague-employee'!D2:D61,TRUE()) -> 60 | E23: =COUNTIF('AG_vague-employee'!D2:D61,FALSE()) -> 0 | F23: =IF($C23=0,0,D23/$C23) -> 1 | G23: =IF($C23=0,0,E23/$C23) -> 0 | H23: =COUNTIF('AG_vague-employee'!G2:G61,TRUE()) -> 60 | I23: =COUNTIF('AG_vague-employee'!G2:G61,FALSE()) -> 0 | J23: =IF($C23=0,0,H23/$C23) -> 1 | K23: =IF($C23=0,0,I23/$C23) -> 0
A24: AG_vague-group_info | B24: Agent | C24: =D24+E24 -> 60 | D24: =COUNTIF('AG_vague-group_info'!D2:D61,TRUE()) -> 60 | E24: =COUNTIF('AG_vague-group_info'!D2:D61,FALSE()) -> 0 | F24: =IF($C24=0,0,D24/$C24) -> 1 | G24: =IF($C24=0,0,E24/$C24) -> 0 | H24: =COUNTIF('AG_vague-group_info'!G2:G61,TRUE()) -> 60 | I24: =COUNTIF('AG_vague-group_info'!G2:G61,FALSE()) -> 0 | J24: =IF($C24=0,0,H24/$C24) -> 1 | K24: =IF($C24=0,0,I24/$C24) -> 0
A25: AG_vague-inquire | B25: Agent | C25: =D25+E25 -> 60 | D25: =COUNTIF('AG_vague-inquire'!D2:D61,TRUE()) -> 59 | E25: =COUNTIF('AG_vague-inquire'!D2:D61,FALSE()) -> 1 | F25: =IF($C25=0,0,D25/$C25) -> 0.98333333 | G25: =IF($C25=0,0,E25/$C25) -> 0.016666667 | H25: =COUNTIF('AG_vague-inquire'!G2:G61,TRUE()) -> 59 | I25: =COUNTIF('AG_vague-inquire'!G2:G61,FALSE()) -> 1 | J25: =IF($C25=0,0,H25/$C25) -> 0.98333333 | K25: =IF($C25=0,0,I25/$C25) -> 0.016666667
A26: AG_vague-membership | B26: Agent | C26: =D26+E26 -> 60 | D26: =COUNTIF('AG_vague-membership'!D2:D61,TRUE()) -> 60 | E26: =COUNTIF('AG_vague-membership'!D2:D61,FALSE()) -> 0 | F26: =IF($C26=0,0,D26/$C26) -> 1 | G26: =IF($C26=0,0,E26/$C26) -> 0 | H26: =COUNTIF('AG_vague-membership'!G2:G61,TRUE()) -> 60 | I26: =COUNTIF('AG_vague-membership'!G2:G61,FALSE()) -> 0 | J26: =IF($C26=0,0,H26/$C26) -> 1 | K26: =IF($C26=0,0,I26/$C26) -> 0
A27: AG_vague-problem | B27: Agent | C27: =D27+E27 -> 60 | D27: =COUNTIF('AG_vague-problem'!D2:D61,TRUE()) -> 58 | E27: =COUNTIF('AG_vague-problem'!D2:D61,FALSE()) -> 2 | F27: =IF($C27=0,0,D27/$C27) -> 0.96666667 | G27: =IF($C27=0,0,E27/$C27) -> 0.033333333 | H27: =COUNTIF('AG_vague-problem'!G2:G61,TRUE()) -> 58 | I27: =COUNTIF('AG_vague-problem'!G2:G61,FALSE()) -> 2 | J27: =IF($C27=0,0,H27/$C27) -> 0.96666667 | K27: =IF($C27=0,0,I27/$C27) -> 0.033333333
A28: AG_vague-service | B28: Agent | C28: =D28+E28 -> 60 | D28: =COUNTIF('AG_vague-service'!D2:D61,TRUE()) -> 59 | E28: =COUNTIF('AG_vague-service'!D2:D61,FALSE()) -> 1 | F28: =IF($C28=0,0,D28/$C28) -> 0.98333333 | G28: =IF($C28=0,0,E28/$C28) -> 0.016666667 | H28: =COUNTIF('AG_vague-service'!G2:G61,TRUE()) -> 59 | I28: =COUNTIF('AG_vague-service'!G2:G61,FALSE()) -> 1 | J28: =IF($C28=0,0,H28/$C28) -> 0.98333333 | K28: =IF($C28=0,0,I28/$C28) -> 0.016666667
A29: AG_vague-status | B29: Agent | C29: =D29+E29 -> 60 | D29: =COUNTIF('AG_vague-status'!D2:D61,TRUE()) -> 59 | E29: =COUNTIF('AG_vague-status'!D2:D61,FALSE()) -> 1 | F29: =IF($C29=0,0,D29/$C29) -> 0.98333333 | G29: =IF($C29=0,0,E29/$C29) -> 0.016666667 | H29: =COUNTIF('AG_vague-status'!G2:G61,TRUE()) -> 59 | I29: =COUNTIF('AG_vague-status'!G2:G61,FALSE()) -> 1 | J29: =IF($C29=0,0,H29/$C29) -> 0.98333333 | K29: =IF($C29=0,0,I29/$C29) -> 0.016666667
A30: AG_vague-tax | B30: Agent | C30: =D30+E30 -> 60 | D30: =COUNTIF('AG_vague-tax'!D2:D61,TRUE()) -> 60 | E30: =COUNTIF('AG_vague-tax'!D2:D61,FALSE()) -> 0 | F30: =IF($C30=0,0,D30/$C30) -> 1 | G30: =IF($C30=0,0,E30/$C30) -> 0 | H30: =COUNTIF('AG_vague-tax'!G2:G61,TRUE()) -> 60 | I30: =COUNTIF('AG_vague-tax'!G2:G61,FALSE()) -> 0 | J30: =IF($C30=0,0,H30/$C30) -> 1 | K30: =IF($C30=0,0,I30/$C30) -> 0
A31: AG_vague-vague | B31: Agent | C31: =D31+E31 -> 60 | D31: =COUNTIF('AG_vague-vague'!D2:D61,TRUE()) -> 58 | E31: =COUNTIF('AG_vague-vague'!D2:D61,FALSE()) -> 2 | F31: =IF($C31=0,0,D31/$C31) -> 0.96666667 | G31: =IF($C31=0,0,E31/$C31) -> 0.033333333 | H31: =COUNTIF('AG_vague-vague'!G2:G61,TRUE()) -> 58 | I31: =COUNTIF('AG_vague-vague'!G2:G61,FALSE()) -> 2 | J31: =IF($C31=0,0,H31/$C31) -> 0.96666667 | K31: =IF($C31=0,0,I31/$C31) -> 0.033333333
A32: BL_change-autopay | B32: Billing | C32: =D32+E32 -> 60 | D32: =COUNTIF('BL_change-autopay'!D2:D61,TRUE()) -> 21 | E32: =COUNTIF('BL_change-autopay'!D2:D61,FALSE()) -> 39 | F32: =IF($C32=0,0,D32/$C32) -> 0.35 | G32: =IF($C32=0,0,E32/$C32) -> 0.65 | H32: =COUNTIF('BL_change-autopay'!G2:G61,TRUE()) -> 58 | I32: =COUNTIF('BL_change-autopay'!G2:G61,FALSE()) -> 2 | J32: =IF($C32=0,0,H32/$C32) -> 0.96666667 | K32: =IF($C32=0,0,I32/$C32) -> 0.033333333
A33: BL_change-bank_account | B33: Billing | C33: =D33+E33 -> 60 | D33: =COUNTIF('BL_change-bank_account'!D2:D61,TRUE()) -> 2 | E33: =COUNTIF('BL_change-bank_account'!D2:D61,FALSE()) -> 58 | F33: =IF($C33=0,0,D33/$C33) -> 0.033333333 | G33: =IF($C33=0,0,E33/$C33) -> 0.96666667 | H33: =COUNTIF('BL_change-bank_account'!G2:G61,TRUE()) -> 58 | I33: =COUNTIF('BL_change-bank_account'!G2:G61,FALSE()) -> 2 | J33: =IF($C33=0,0,H33/$C33) -> 0.96666667 | K33: =IF($C33=0,0,I33/$C33) -> 0.033333333
A34: BL_change-billing | B34: Billing | C34: =D34+E34 -> 60 | D34: =COUNTIF('BL_change-billing'!D2:D61,TRUE()) -> 45 | E34: =COUNTIF('BL_change-billing'!D2:D61,FALSE()) -> 15 | F34: =IF($C34=0,0,D34/$C34) -> 0.75 | G34: =IF($C34=0,0,E34/$C34) -> 0.25 | H34: =COUNTIF('BL_change-billing'!G2:G61,TRUE()) -> 56 | I34: =COUNTIF('BL_change-billing'!G2:G61,FALSE()) -> 4 | J34: =IF($C34=0,0,H34/$C34) -> 0.93333333 | K34: =IF($C34=0,0,I34/$C34) -> 0.066666667
A35: BL_inquire-autopay | B35: Billing | C35: =D35+E35 -> 60 | D35: =COUNTIF('BL_inquire-autopay'!D2:D61,TRUE()) -> 10 | E35: =COUNTIF('BL_inquire-autopay'!D2:D61,FALSE()) -> 50 | F35: =IF($C35=0,0,D35/$C35) -> 0.16666667 | G35: =IF($C35=0,0,E35/$C35) -> 0.83333333 | H35: =COUNTIF('BL_inquire-autopay'!G2:G61,TRUE()) -> 57 | I35: =COUNTIF('BL_inquire-autopay'!G2:G61,FALSE()) -> 3 | J35: =IF($C35=0,0,H35/$C35) -> 0.95 | K35: =IF($C35=0,0,I35/$C35) -> 0.05
A36: BL_inquire-balance | B36: Billing | C36: =D36+E36 -> 60 | D36: =COUNTIF('BL_inquire-balance'!D2:D61,TRUE()) -> 23 | E36: =COUNTIF('BL_inquire-balance'!D2:D61,FALSE()) -> 37 | F36: =IF($C36=0,0,D36/$C36) -> 0.38333333 | G36: =IF($C36=0,0,E36/$C36) -> 0.61666667 | H36: =COUNTIF('BL_inquire-balance'!G2:G61,TRUE()) -> 54 | I36: =COUNTIF('BL_inquire-balance'!G2:G61,FALSE()) -> 6 | J36: =IF($C36=0,0,H36/$C36) -> 0.9 | K36: =IF($C36=0,0,I36/$C36) -> 0.1
A37: BL_inquire-billing | B37: Billing | C37: =D37+E37 -> 60 | D37: =COUNTIF('BL_inquire-billing'!D2:D61,TRUE()) -> 33 | E37: =COUNTIF('BL_inquire-billing'!D2:D61,FALSE()) -> 27 | F37: =IF($C37=0,0,D37/$C37) -> 0.55 | G37: =IF($C37=0,0,E37/$C37) -> 0.45 | H37: =COUNTIF('BL_inquire-billing'!G2:G61,TRUE()) -> 57 | I37: =COUNTIF('BL_inquire-billing'!G2:G61,FALSE()) -> 3 | J37: =IF($C37=0,0,H37/$C37) -> 0.95 | K37: =IF($C37=0,0,I37/$C37) -> 0.05
A38: BL_inquire-credit | B38: Billing | C38: =D38+E38 -> 60 | D38: =COUNTIF('BL_inquire-credit'!D2:D61,TRUE()) -> 19 | E38: =COUNTIF('BL_inquire-credit'!D2:D61,FALSE()) -> 41 | F38: =IF($C38=0,0,D38/$C38) -> 0.31666667 | G38: =IF($C38=0,0,E38/$C38) -> 0.68333333 | H38: =COUNTIF('BL_inquire-credit'!G2:G61,TRUE()) -> 55 | I38: =COUNTIF('BL_inquire-credit'!G2:G61,FALSE()) -> 5 | J38: =IF($C38=0,0,H38/$C38) -> 0.91666667 | K38: =IF($C38=0,0,I38/$C38) -> 0.083333333
A39: BL_inquire-mlr | B39: Billing | C39: =D39+E39 -> 60 | D39: =COUNTIF('BL_inquire-mlr'!D2:D61,TRUE()) -> 28 | E39: =COUNTIF('BL_inquire-mlr'!D2:D61,FALSE()) -> 32 | F39: =IF($C39=0,0,D39/$C39) -> 0.46666667 | G39: =IF($C39=0,0,E39/$C39) -> 0.53333333 | H39: =COUNTIF('BL_inquire-mlr'!G2:G61,TRUE()) -> 60 | I39: =COUNTIF('BL_inquire-mlr'!G2:G61,FALSE()) -> 0 | J39: =IF($C39=0,0,H39/$C39) -> 1 | K39: =IF($C39=0,0,I39/$C39) -> 0
A40: BL_inquire-notice_overdue | B40: Billing | C40: =D40+E40 -> 60 | D40: =COUNTIF('BL_inquire-notice_overdue'!D2:D61,TRUE()) -> 6 | E40: =COUNTIF('BL_inquire-notice_overdue'!D2:D61,FALSE()) -> 54 | F40: =IF($C40=0,0,D40/$C40) -> 0.1 | G40: =IF($C40=0,0,E40/$C40) -> 0.9 | H40: =COUNTIF('BL_inquire-notice_overdue'!G2:G61,TRUE()) -> 51 | I40: =COUNTIF('BL_inquire-notice_overdue'!G2:G61,FALSE()) -> 9 | J40: =IF($C40=0,0,H40/$C40) -> 0.85 | K40: =IF($C40=0,0,I40/$C40) -> 0.15
...

Sheet Playbook Summary
A1: Playbook | B1: Total | C1: Head Pass | D1: Head Fail | E1: Head Pass % | F1: Head Fail % | G1: Sub Pass | H1: Sub Fail | I1: Sub Pass % | J1: Sub Fail %
A2: Agent | B2: =SUMIF(Summary!$B$2:$B$186,A2,Summary!$C$2:$C$186) -> 1800 | C2: =SUMIF(Summary!$B$2:$B$186,A2,Summary!$D$2:$D$186) -> 1780 | D2: =SUMIF(Summary!$B$2:$B$186,A2,Summary!$E$2:$E$186) -> 20 | E2: =IF($B2=0,0,C2/$B2) -> 0.98888889 | F2: =IF($B2=0,0,D2/$B2) -> 0.011111111 | G2: =SUMIF(Summary!$B$2:$B$186,A2,Summary!$H$2:$H$186) -> 1779 | H2: =SUMIF(Summary!$B$2:$B$186,A2,Summary!$I$2:$I$186) -> 21 | I2: =IF($B2=0,0,G2/$B2) -> 0.98833333 | J2: =IF($B2=0,0,H2/$B2) -> 0.011666667
A3: Benefits | B3: =SUMIF(Summary!$B$2:$B$186,A3,Summary!$C$2:$C$186) -> 900 | C3: =SUMIF(Summary!$B$2:$B$186,A3,Summary!$D$2:$D$186) -> 739 | D3: =SUMIF(Summary!$B$2:$B$186,A3,Summary!$E$2:$E$186) -> 161 | E3: =IF($B3=0,0,C3/$B3) -> 0.82111111 | F3: =IF($B3=0,0,D3/$B3) -> 0.17888889 | G3: =SUMIF(Summary!$B$2:$B$186,A3,Summary!$H$2:$H$186) -> 887 | H3: =SUMIF(Summary!$B$2:$B$186,A3,Summary!$I$2:$I$186) -> 13 | I3: =IF($B3=0,0,G3/$B3) -> 0.98555556 | J3: =IF($B3=0,0,H3/$B3) -> 0.014444444
A4: Billing | B4: =SUMIF(Summary!$B$2:$B$186,A4,Summary!$C$2:$C$186) -> 2040 | C4: =SUMIF(Summary!$B$2:$B$186,A4,Summary!$D$2:$D$186) -> 1059 | D4: =SUMIF(Summary!$B$2:$B$186,A4,Summary!$E$2:$E$186) -> 981 | E4: =IF($B4=0,0,C4/$B4) -> 0.51911765 | F4: =IF($B4=0,0,D4/$B4) -> 0.48088235 | G4: =SUMIF(Summary!$B$2:$B$186,A4,Summary!$H$2:$H$186) -> 1967 | H4: =SUMIF(Summary!$B$2:$B$186,A4,Summary!$I$2:$I$186) -> 73 | I4: =IF($B4=0,0,G4/$B4) -> 0.96421569 | J4: =IF($B4=0,0,H4/$B4) -> 0.035784314
A5: Claims | B5: =SUMIF(Summary!$B$2:$B$186,A5,Summary!$C$2:$C$186) -> 660 | C5: =SUMIF(Summary!$B$2:$B$186,A5,Summary!$D$2:$D$186) -> 572 | D5: =SUMIF(Summary!$B$2:$B$186,A5,Summary!$E$2:$E$186) -> 88 | E5: =IF($B5=0,0,C5/$B5) -> 0.86666667 | F5: =IF($B5=0,0,D5/$B5) -> 0.13333333 | G5: =SUMIF(Summary!$B$2:$B$186,A5,Summary!$H$2:$H$186) -> 595 | H5: =SUMIF(Summary!$B$2:$B$186,A5,Summary!$I$2:$I$186) -> 65 | I5: =IF($B5=0,0,G5/$B5) -> 0.90151515 | J5: =IF($B5=0,0,H5/$B5) -> 0.098484848
A6: Eligibility | B6: =SUMIF(Summary!$B$2:$B$186,A6,Summary!$C$2:$C$186) -> 3120 | C6: =SUMIF(Summary!$B$2:$B$186,A6,Summary!$D$2:$D$186) -> 3100 | D6: =SUMIF(Summary!$B$2:$B$186,A6,Summary!$E$2:$E$186) -> 20 | E6: =IF($B6=0,0,C6/$B6) -> 0.99358974 | F6: =IF($B6=0,0,D6/$B6) -> 0.0064102564 | G6: =SUMIF(Summary!$B$2:$B$186,A6,Summary!$H$2:$H$186) -> 3094 | H6: =SUMIF(Summary!$B$2:$B$186,A6,Summary!$I$2:$I$186) -> 26 | I6: =IF($B6=0,0,G6/$B6) -> 0.99166667 | J6: =IF($B6=0,0,H6/$B6) -> 0.0083333333
A7: Head Intent Detection | B7: =SUMIF(Summary!$B$2:$B$186,A7,Summary!$C$2:$C$186) -> 780 | C7: =SUMIF(Summary!$B$2:$B$186,A7,Summary!$D$2:$D$186) -> 639 | D7: =SUMIF(Summary!$B$2:$B$186,A7,Summary!$E$2:$E$186) -> 141 | E7: =IF($B7=0,0,C7/$B7) -> 0.81923077 | F7: =IF($B7=0,0,D7/$B7) -> 0.18076923 | G7: NA | H7: NA | I7: NA | J7: NA
A8: Other Intents | B8: =SUMIF(Summary!$B$2:$B$186,A8,Summary!$C$2:$C$186) -> 1800 | C8: =SUMIF(Summary!$B$2:$B$186,A8,Summary!$D$2:$D$186) -> 1706 | D8: =SUMIF(Summary!$B$2:$B$186,A8,Summary!$E$2:$E$186) -> 94 | E8: =IF($B8=0,0,C8/$B8) -> 0.94777778 | F8: =IF($B8=0,0,D8/$B8) -> 0.052222222 | G8: =SUMIF(Summary!$B$2:$B$186,A8,Summary!$H$2:$H$186) -> 1705 | H8: =SUMIF(Summary!$B$2:$B$186,A8,Summary!$I$2:$I$186) -> 95 | I8: =IF($B8=0,0,G8/$B8) -> 0.94722222 | J8: =IF($B8=0,0,H8/$B8) -> 0.052777778
A9: Steering | B9: =SUMIF(Summary!$B$2:$B$186,A9,Summary!$C$2:$C$186) -> 0 | C9: =SUMIF(Summary!$B$2:$B$186,A9,Summary!$D$2:$D$186) -> 0 | D9: =SUMIF(Summary!$B$2:$B$186,A9,Summary!$E$2:$E$186) -> 0 | E9: =IF($B9=0,0,C9/$B9) -> 0 | F9: =IF($B9=0,0,D9/$B9) -> 0 | G9: =SUMIF(Summary!$B$2:$B$186,A9,Summary!$H$2:$H$186) -> 0 | H9: =SUMIF(Summary!$B$2:$B$186,A9,Summary!$I$2:$I$186) -> 0 | I9: =IF($B9=0,0,G9/$B9) -> 0 | J9: =IF($B9=0,0,H9/$B9) -> 0
A10: TOTAL | B10: =SUM(B2:B9) -> 11100 | C10: =SUM(C2:C9) -> 9595 | D10: =SUM(D2:D9) -> 1505 | E10: =IF($B10=0,0,C10/$B10) -> 0.86441441 | F10: =IF($B10=0,0,D10/$B10) -> 0.13558559 | G10: =SUM(G2:G9) -> 10027 | H10: =SUM(H2:H9) -> 293 | I10: =IF((G10+H10)=0,0,G10/(G10+H10)) -> 0.97160853 | J10: =IF((G10+H10)=0,0,H10/(G10+H10)) -> 0.028391473

Sheet AG_change-account
A1: utterance | B1: expected_head_intent | C1: detected_head_intent | D1: head_intent_match | E1: expected_sub_intent | F1: detected_sub_intent | G1: sub_intent_match | H1: error
A2: Remove account contact | B2: agent | C2: agent | D2: =TRUE() -> TRUE | E2: change-account | F2: change-account | G2: =TRUE() -> TRUE
A3: Trying to change an employee's information | B3: agent | C3: agent | D3: =TRUE() -> TRUE | E3: change-account | F3: change-account | G3: =TRUE() -> TRUE
A4: Update company profile | B4: agent | C4: agent | D4: =TRUE() -> TRUE | E4: change-account | F4: change-account | G4: =TRUE() -> TRUE
A5: Update contact | B5: agent | C5: agent | D5: =TRUE() -> TRUE | E5: change-account | F5: change-account | G5: =TRUE() -> TRUE
A6: Update contact information | B6: agent | C6: agent | D6: =TRUE() -> TRUE | E6: change-account | F6: change-account | G6: =TRUE() -> TRUE
A7: Update membership | B7: agent | C7: agent | D7: =TRUE() -> TRUE | E7: change-account | F7: change-account | G7: =TRUE() -> TRUE
A8: Update salary information | B8: agent | C8: agent | D8: =TRUE() -> TRUE | E8: change-account | F8: change-account | G8: =TRUE() -> TRUE
A9: Want to make change to subscriber | B9: agent | C9: agent | D9: =TRUE() -> TRUE | E9: change-account | F9: change-account | G9: =TRUE() -> TRUE
A10: Would like to change the account information on the united healthcare secure email | B10: agent | C10: agent | D10: =TRUE() -> TRUE | E10: change-account | F10: change-account | G10: =TRUE() -> TRUE
A11: Wrong social_security number | B11: agent | C11: agent | D11: =TRUE() -> TRUE | E11: change-account | F11: change-account | G11: =TRUE() -> TRUE
A12: I need help with remove account contact. | B12: agent | C12: agent | D12: =TRUE() -> TRUE | E12: change-account | F12: change-account | G12: =TRUE() -> TRUE
A13: I need help with trying to change an employee's information. | B13: agent | C13: agent | D13: =TRUE() -> TRUE | E13: change-account | F13: change-account | G13: =TRUE() -> TRUE
... A61: Calling regarding wrong social_security number. | B61: agent | C61: agent | D61: =TRUE() -> TRUE | E61: change-account | F61: change-account | G61: =TRUE() -> TRUE
A62: HEAD INTENT ACCURACY | D62: 100.0%
A63: SUB INTENT ACCURACY | G63: 100.0%

Sheet AG_change-address
A1: utterance | B1: expected_head_intent | C1: detected_head_intent | D1: head_intent_match | E1: expected_sub_intent | F1: detected_sub_intent | G1: sub_intent_match | H1: error
A2: Update address | B2: agent | C2: agent | D2: =TRUE() -> TRUE | E2: change-address | F2: change-address | G2: =TRUE() -> TRUE
A3: Change address | B3: agent | C3: agent | D3: =TRUE() -> TRUE | E3: change-address | F3: change-address | G3: =TRUE() -> TRUE
A4: Update employee address | B4: agent | C4: agent | D4: =TRUE() -> TRUE | E4: change-address | F4: change-address | G4: =TRUE() -> TRUE
A5: Update company address | B5: agent | C5: agent | D5: =TRUE() -> TRUE | E5: change-address | F5: change-address | G5: =TRUE() -> TRUE
A6: Update mailing address | B6: agent | C6: agent | D6: =TRUE() -> TRUE | E6: change-address | F6: change-address | G6: =TRUE() -> TRUE
A7: Change subscriber address | B7: agent | C7: agent | D7: =TRUE() -> TRUE | E7: change-address | F7: change-address | G7: =TRUE() -> TRUE
A8: Update employer address | B8: agent | C8: agent | D8: =TRUE() -> TRUE | E8: change-address | F8: change-address | G8: =TRUE() -> TRUE
A9: Correct address | B9: agent | C9: agent | D9: =TRUE() -> TRUE | E9: change-address | F9: change-address | G9: =TRUE() -> TRUE
A10: Request address change | B10: agent | C10: agent | D10: =TRUE() -> TRUE | E10: change-address | F10: change-address | G10: =TRUE() -> TRUE
A11: Need to change address | B11: agent | C11: agent | D11: =TRUE() -> TRUE | E11: change-address | F11: change-address | G11: =TRUE() -> TRUE
A12: Update address on policy | B12: agent | C12: agent | D12: =TRUE() -> TRUE | E12: change-address | F12: change-address | G12: =TRUE() -> TRUE
A13: Report address change | B13: agent | C13: agent | D13: =TRUE() -> TRUE | E13: change-address | F13: change-address | G13: =TRUE() -> TRUE
... A61: Looking for help with report address change. | B61: agent | C61: agent | D61: =TRUE() -> TRUE | E61: change-address | F61: change-address | G61: =TRUE() -> TRUE
A62: HEAD INTENT ACCURACY | D62: 100.0%
A63: SUB INTENT ACCURACY | G63: 100.0%

Sheet AG_change-admin
A1: utterance | B1: expected_head_intent | C1: detected_head_intent | D1: head_intent_match | E1: expected_sub_intent | F1: detected_sub_intent | G1: sub_intent_match | H1: error
A2: Transfer of administrator | B2: agent | C2: agent | D2: =TRUE() -> TRUE | E2: change-admin | F2: change-admin | G2: =TRUE() -> TRUE
A3: Want to change admin | B3: agent | C3: agent | D3: =TRUE() -> TRUE | E3: change-admin | F3: change-admin | G3: =TRUE() -> TRUE
A4: Admin change | B4: agent | C4: agent | D4: =TRUE() -> TRUE | E4: change-admin | F4: change-admin | G4: =TRUE() -> TRUE
A5: I need help with transfer of administrator. | B5: agent | C5: agent | D5: =TRUE() -> TRUE | E5: change-admin | F5: change-admin | G5: =TRUE() -> TRUE
A6: I need help with want to change admin. | B6: agent | C6: agent | D6: =TRUE() -> TRUE | E6: change-admin | F6: change-admin | G6: =TRUE() -> TRUE
A7: I need help with admin change. | B7: agent | C7: agent | D7: =TRUE() -> TRUE | E7: change-admin | F7: change-admin | G7: =TRUE() -> TRUE
A8: Calling about transfer of administrator. | B8: agent | C8: agent | D8: =TRUE() -> TRUE | E8: change-admin | F8: change-admin | G8: =TRUE() -> TRUE
A9: Calling about want to change admin. | B9: agent | C9: agent | D9: =TRUE() -> TRUE | E9: change-admin | F9: change-admin | G9: =TRUE() -> TRUE
A10: Calling about admin change. | B10: agent | C10: agent | D10: =TRUE() -> TRUE | E10: change-admin | F10: change-admin | G10: =TRUE() -> TRUE
A11: I have a question about transfer of administrator. | B11: agent | C11: agent | D11: =TRUE() -> TRUE | E11: change-admin | F11: change-admin | G11: =TRUE() -> TRUE
A12: I have a question about want to change admin. | B12: agent | C12: agent | D12: =TRUE() -> TRUE | E12: change-admin | F12: change-admin | G12: =TRUE() -> TRUE
A13: I have a question about admin change. | B13: agent | C13: agent | D13: =TRUE() -> TRUE | E13: change-admin | F13: change-admin | G13: =TRUE() -> TRUE
... A61: I'm trying to get help with admin change. | B61: agent | C61: agent | D61: =TRUE() -> TRUE | E61: change-admin | F61: change-admin | G61: =TRUE() -> TRUE
A62: HEAD INTENT ACCURACY | D62: 100.0%
A63: SUB INTENT ACCURACY | G63: 100.0%

Sheet AG_change-dependent_info
A1: utterance | B1: expected_head_intent | C1: detected_head_intent | D1: head_intent_match | E1: expected_sub_intent | F1: detected_sub_intent | G1: sub_intent_match | H1: error
A2: I need to update a dependent address | B2: agent | C2: agent | D2: =TRUE() -> TRUE | E2: change-dependent_info | F2: change-dependent_info | G2: =TRUE() -> TRUE
A3: To change an address for a married dependent | B3: agent | C3: agent | D3: =TRUE() -> TRUE | E3: change-dependent_info | F3: change-dependent_info | G3: =TRUE() -> TRUE
A4: Update a social of a dependent | B4: agent | C4: agent | D4: =TRUE() -> TRUE | E4: change-dependent_info | F4: change-dependent_info | G4: =TRUE() -> TRUE
A5: Updating dependent information | B5: agent | C5: agent | D5: =TRUE() -> TRUE | E5: change-dependent_info | F5: change-dependent_info | G5: =TRUE() -> TRUE
A6: I need help with i need to update a dependent address. | B6: agent | C6: agent | D6: =TRUE() -> TRUE | E6: change-dependent_info | F6: change-dependent_info | G6: =TRUE() -> TRUE
A7: I need help with update a social of a dependent. | B7: agent | C7: agent | D7: =TRUE() -> TRUE | E7: change-dependent_info | F7: change-dependent_info | G7: =TRUE() -> TRUE
A8: I need help with updating dependent information. | B8: agent | C8: agent | D8: =TRUE() -> TRUE | E8: change-dependent_info | F8: change-dependent_info | G8: =TRUE() -> TRUE
A9: Calling about i need to update a dependent address. | B9: agent | C9: agent | D9: =TRUE() -> TRUE | E9: change-dependent_info | F9: change-dependent_info | G9: =TRUE() -> TRUE
A10: Calling about update a social of a dependent. | B10: agent | C10: agent | D10: =TRUE() -> TRUE | E10: change-dependent_info | F10: change-dependent_info | G10: =TRUE() -> TRUE
A11: Calling about updating dependent information. | B11: agent | C11: agent | D11: =TRUE() -> TRUE | E11: change-dependent_info | F11: change-dependent_info | G11: =TRUE() -> TRUE
A12: I have a question about i need to update a dependent address. | B12: agent | C12: agent | D12: =TRUE() -> TRUE | E12: change-dependent_info | F12: change-dependent_info | G12: =TRUE() -> TRUE
A13: I have a question about update a social of a dependent. | B13: agent | C13: agent | D13: =TRUE() -> TRUE | E13: change-dependent_info | F13: change-dependent_info | G13: =TRUE() -> TRUE
... A61: I'm trying to get help with update a social of a dependent. | B61: agent | C61: agent | D61: =TRUE() -> TRUE | E61: change-dependent_info | F61: change-dependent_info | G61: =TRUE() -> TRUE
A62: HEAD INTENT ACCURACY | D62: 100.0%
A63: SUB INTENT ACCURACY | G63: 100.0%

Sheet AG_change-group_info
A1: utterance | B1: expected_head_intent | C1: detected_head_intent | D1: head_intent_match | E1: expected_sub_intent | F1: detected_sub_intent | G1: sub_intent_match | H1: error
A2: Manage group | B2: agent | C2: agent | D2: =TRUE() -> TRUE | E2: change-group_info | F2: change-group_info | G2: =TRUE() -> TRUE
A3: Receipt of group information update form | B3: agent | C3: agent | D3: =TRUE() -> TRUE | E3: change-group_info | F3: change-group_info | G3: =TRUE() -> TRUE
A4: Small group changes terminations | B4: agent | C4: agent | D4: =TRUE() -> TRUE | E4: change-group_info | F4: change-group_info | G4: =TRUE() -> TRUE
A5: Update group information | B5: agent | C5: agent | D5: =TRUE() -> TRUE | E5: change-group_info | F5: change-group_info | G5: =TRUE() -> TRUE
A6: Upgrade a group | B6: agent | C6: agent | D6: =TRUE() -> TRUE | E6: change-group_info | F6: change-group_info | G6: =TRUE() -> TRUE
A7: I need help with manage group. | B7: agent | C7: agent | D7: =TRUE() -> TRUE | E7: change-group_info | F7: change-group_info | G7: =TRUE() -> TRUE
A8: I need help with receipt of group information update form. | B8: agent | C8: agent | D8: =TRUE() -> TRUE | E8: change-group_info | F8: change-group_info | G8: =TRUE() -> TRUE
A9: I need help with small group changes terminations. | B9: agent | C9: agent | D9: =TRUE() -> TRUE | E9: change-group_info | F9: change-group_info | G9: =TRUE() -> TRUE
A10: I need help with update group information. | B10: agent | C10: agent | D10: =TRUE() -> TRUE | E10: change-group_info | F10: change-group_info | G10: =TRUE() -> TRUE
A11: I need help with upgrade a group. | B11: agent | C11: agent | D11: =TRUE() -> TRUE | E11: change-group_info | F11: change-group_info | G11: =TRUE() -> TRUE
A12: Calling about manage group. | B12: agent | C12: agent | D12: =TRUE() -> TRUE | E12: change-group_info | F12: change-group_info | G12: =TRUE() -> TRUE
A13: Calling about receipt of group information update form. | B13: agent | C13: agent | D13: =TRUE() -> TRUE | E13: change-group_info | F13: change-group_info | G13: =TRUE() -> TRUE
... A46: Help with upgrade a group. | B46: agent | C46: agent | D46: =TRUE() -> TRUE | E46: change-group_info | F46: change-group_info | G46: =TRUE() -> TRUE
A47: Question about manage group. | B47: agent | D47: =FALSE() -> FALSE | E47: change-group_info | G47: =FALSE() -> FALSE
A48: Question about receipt of group information update form. | B48: agent | C48: agent | D48: =TRUE() -> TRUE | E48: change-group_info | F48: change-group_info | G48: =TRUE() -> TRUE
A49: Question about small group changes terminations. | B49: agent | C49: agent | D49: =TRUE() -> TRUE | E49: change-group_info | F49: change-group_info | G49: =TRUE() -> TRUE
A50: Question about update group information. | B50: agent | C50: agent | D50: =TRUE() -> TRUE | E50: change-group_info | F50: change-group_info | G50: =TRUE() -> TRUE
A51: Question about upgrade a group. | B51: agent | C51: agent | D51: =TRUE() -> TRUE | E51: change-group_info | F51: change-group_info | G51: =TRUE() -> TRUE
A52: I'm calling about manage group. | B52: agent | C52: agent | D52: =TRUE() -> TRUE | E52: change-group_info | F52: change-group_info | G52: =TRUE() -> TRUE
A53: I'm calling about receipt of group information update form. | B53: agent | C53: agent | D53: =TRUE() -> TRUE | E53: change-group_info | F53: change-group_info | G53: =TRUE() -> TRUE
A54: I'm calling about small group changes terminations. | B54: agent | C54: agent | D54: =TRUE() -> TRUE | E54: change-group_info | F54: change-group_info | G54: =TRUE() -> TRUE
A55: I'm calling about update group information. | B55: agent | C55: agent | D55: =TRUE() -> TRUE | E55: change-group_info | F55: change-group_info | G55: =TRUE() -> TRUE
A56: I'm calling about upgrade a group. | B56: agent | C56: agent | D56: =TRUE() -> TRUE | E56: change-group_info | F56: change-group_info | G56: =TRUE() -> TRUE
A57: I'd like information on manage group. | B57: agent | C57: agent | D57: =TRUE() -> TRUE | E57: change-group_info | F57: change-group_info | G57: =TRUE() -> TRUE
A58: I'd like information on receipt of group information update form. | B58: agent | C58: agent | D58: =TRUE() -> TRUE | E58: change-group_info | F58: change-group_info | G58: =TRUE() -> TRUE
A59: I'd like information on small group changes terminations. | B59: agent | C59: agent | D59: =TRUE() -> TRUE | E59: change-group_info | F59: change-group_info | G59: =TRUE() -> TRUE
... A61: I'd like information on upgrade a group. | B61: agent | C61: agent | D61: =TRUE() -> TRUE | E61: change-group_info | F61: change-group_info | G61: =TRUE() -> TRUE
A62: HEAD INTENT ACCURACY | D62: 98.33%
A63: SUB INTENT ACCURACY | G63: 98.33%

Sheet AG_change-provider
A1: utterance | B1: expected_head_intent | C1: detected_head_intent | D1: head_intent_match | E1: expected_sub_intent | F1: detected_sub_intent | G1: sub_intent_match | H1: error
A2: Member member upset because primary care provider was changed | B2: agent | C2: agent | D2: =TRUE() -> TRUE | E2: change-provider | F2: change-provider | G2: =TRUE() -> TRUE
A3: Need to change dependents physician | B3: agent | C3: agent | D3: =TRUE() -> TRUE | E3: change-provider | F3: change-provider | G3: =TRUE() -> TRUE
A4: Need to change primary care physician for dependent | B4: agent | C4: agent | D4: =TRUE() -> TRUE | E4: change-provider | F4: change-provider | G4: =TRUE() -> TRUE
A5: P c p change | B5: agent | C5: agent | D5: =TRUE() -> TRUE | E5: change-provider | F5: change-provider | G5: =TRUE() -> TRUE
A6: P_c_p update | B6: agent | C6: agent | D6: =TRUE() -> TRUE | E6: change-provider | F6: change-provider | G6: =TRUE() -> TRUE
A7: To get the p_c_p updated for two employees of washington street pawn brokers | B7: agent | C7: agent | D7: =TRUE() -> TRUE | E7: change-provider | F7: change-provider | G7: =TRUE() -> TRUE
A8: Update primary care physician | B8: agent | C8: agent | D8: =TRUE() -> TRUE | E8: change-provider | F8: change-provider | G8: =TRUE() -> TRUE
A9: I need help with member member upset because primary care provider was changed. | B9: agent | C9: agent | D9: =TRUE() -> TRUE | E9: change-provider | F9: change-provider | G9: =TRUE() -> TRUE
A10: I need help with need to change dependents physician. | B10: agent | C10: agent | D10: =TRUE() -> TRUE | E10: change-provider | F10: change-provider | G10: =TRUE() -> TRUE
A11: I need help with need to change primary care physician for dependent. | B11: agent | C11: agent | D11: =TRUE() -> TRUE | E11: change-provider | F11: change-provider | G11: =TRUE() -> TRUE
A12: I need help with p c p change. | B12: agent | C12: agent | D12: =TRUE() -> TRUE | E12: change-provider | F12: change-provider | G12: =TRUE() -> TRUE
A13: I need help with p_c_p update. | B13: agent | C13: agent | D13: =TRUE() -> TRUE | E13: change-provider | F13: change-provider | G13: =TRUE() -> TRUE
... A61: Question about p_c_p update. | B61: agent | C61: agent | D61: =TRUE() -> TRUE | E61: change-provider | F61: change-provider | G61: =TRUE() -> TRUE
A62: HEAD INTENT ACCURACY | D62: 100.0%
A63: SUB INTENT ACCURACY | G63: 100.0%

Sheet AG_find-provider
A1: utterance | B1: expected_head_intent | C1: detected_head_intent | D1: head_intent_match | E1: expected_sub_intent | F1: detected_sub_intent | G1: sub_intent_match | H1: error
A2: Find a physician | B2: agent | C2: agent | D2: =TRUE() -> TRUE | E2: find-provider | F2: find-provider | G2: =TRUE() -> TRUE
A3: Need to find a provider | B3: agent | C3: agent | D3: =TRUE() -> TRUE | E3: find-provider | F3: find-provider | G3: =TRUE() -> TRUE
A4: A dentist in p p o network | B4: agent | C4: agent | D4: =TRUE() -> TRUE | E4: find-provider | F4: find-provider | G4: =TRUE() -> TRUE
A5: D m o dentist list | B5: agent | C5: agent | D5: =TRUE() -> TRUE | E5: find-provider | F5: find-provider | G5: =TRUE() -> TRUE
A6: Find an in_network doctor for a client | B6: agent | C6: agent | D6: =TRUE() -> TRUE | E6: find-provider | F6: find-provider | G6: =TRUE() -> TRUE
A7: Finding participating dentist | B7: agent | C7: agent | D7: =TRUE() -> TRUE | E7: find-provider | F7: find-provider | G7: =TRUE() -> TRUE
A8: I need a list of dental dentist | B8: agent | C8: agent | D8: =TRUE() -> TRUE | E8: find-provider | F8: find-provider | G8: =TRUE() -> TRUE
A9: I need a provider directory | B9: agent | C9: agent | D9: =TRUE() -> TRUE | E9: find-provider | F9: find-provider | G9: =TRUE() -> TRUE
A10: I'm looking for a doctor | B10: agent | C10: agent | D10: =TRUE() -> TRUE | E10: find-provider | F10: find-provider | G10: =TRUE() -> TRUE
A11: I'm looking for provider directory online | B11: agent | C11: agent | D11: =TRUE() -> TRUE | E11: find-provider | F11: find-provider | G11: =TRUE() -> TRUE
A12: Looking for lab location | B12: agent | C12: agent | D12: =TRUE() -> TRUE | E12: find-provider | F12: find-provider | G12: =TRUE() -> TRUE
A13: Needed to find urgent care centers through one of my united healthcare groups | B13: agent | C13: agent | D13: =TRUE() -> TRUE | E13: find-provider | F13: find-provider | G13: =TRUE() -> TRUE
... A61: I have a question about provider location. | B61: agent | C61: agent | D61: =TRUE() -> TRUE | E61: find-provider | F61: find-provider | G61: =TRUE() -> TRUE
A62: HEAD INTENT ACCURACY | D62: 100.0%
A63: SUB INTENT ACCURACY | G63: 100.0%

Sheet AG_inquire-account_status
A1: utterance | B1: expected_head_intent | C1: detected_head_intent | D1: head_intent_match | E1: expected_sub_intent | F1: detected_sub_intent | G1: sub_intent_match | H1: error
A2: I want to confirm that we are my account is active | B2: agent | C2: agent | D2: =TRUE() -> TRUE | E2: inquire-account_status | F2: inquire-account_status | G2: =TRUE() -> TRUE
A3: Status of account | B3: agent | C3: agent | D3: =TRUE() -> TRUE | E3: inquire-account_status | F3: inquire-account_status | G3: =TRUE() -> TRUE
A4: I need help with i want to confirm that we are my account is active. | B4: agent | C4: agent | D4: =TRUE() -> TRUE | E4: inquire-account_status | F4: inquire-account_status | G4: =TRUE() -> TRUE
A5: I need help with status of account. | B5: agent | C5: agent | D5: =TRUE() -> TRUE | E5: inquire-account_status | F5: inquire-account_status | G5: =TRUE() -> TRUE
A6: Calling about i want to confirm that we are my account is active. | B6: agent | C6: agent | D6: =TRUE() -> TRUE | E6: inquire-account_status | F6: inquire-account_status | G6: =TRUE() -> TRUE
A7: Calling about status of account. | B7: agent | C7: agent | D7: =TRUE() -> TRUE | E7: inquire-account_status | F7: inquire-account_status | G7: =TRUE() -> TRUE
A8: I have a question about i want to confirm that we are my account is active. | B8: agent | C8: agent | D8: =TRUE() -> TRUE | E8: inquire-account_status | F8: inquire-account_status | G8: =TRUE() -> TRUE
A9: I have a question about status of account. | B9: agent | C9: agent | D9: =TRUE() -> TRUE | E9: inquire-account_status | F9: inquire-account_status | G9: =TRUE() -> TRUE
A10: Looking for help with i want to confirm that we are my account is active. | B10: agent | C10: agent | D10: =TRUE() -> TRUE | E10: inquire-account_status | F10: inquire-account_status | G10: =TRUE() -> TRUE
A11: Looking for help with status of account. | B11: agent | C11: agent | D11: =TRUE() -> TRUE | E11: inquire-account_status | F11: inquire-account_status | G11: =TRUE() -> TRUE
A12: Calling regarding i want to confirm that we are my account is active. | B12: agent | C12: agent | D12: =TRUE() -> TRUE | E12: inquire-account_status | F12: inquire-account_status | G12: =TRUE() -> TRUE
A13: Calling regarding status of account. | B13: agent | C13: agent | D13: =TRUE() -> TRUE | E13: inquire-account_status | F13: inquire-account_status | G13: =TRUE() -> TRUE
... A61: I want to talk to someone about status of account. | B61: agent | C61: agent | D61: =TRUE() -> TRUE | E61: inquire-account_status | F61: inquire-account_status | G61: =TRUE() -> TRUE
A62: HEAD INTENT ACCURACY | D62: 100.0%
A63: SUB INTENT ACCURACY | G63: 100.0%

Sheet AG_report-problem_account
A1: utterance | B1: expected_head_intent | C1: detected_head_intent | D1: head_intent_match | E1: expected_sub_intent | F1: detected_sub_intent | G1: sub_intent_match | H1: error
A2: Report problem account | B2: agent | C2: agent | D2: =TRUE() -> TRUE | E2: report-problem_account | F2: report-problem_account | G2: =TRUE() -> TRUE
A3: I need help with report problem account. | B3: agent | C3: agent | D3: =TRUE() -> TRUE | E3: report-problem_account | F3: report-problem_account | G3: =TRUE() -> TRUE
A4: Calling about report problem account. | B4: agent | C4: agent | D4: =TRUE() -> TRUE | E4: report-problem_account | F4: report-problem_account | G4: =TRUE() -> TRUE
A5: I have a question about report problem account. | B5: agent | C5: agent | D5: =TRUE() -> TRUE | E5: report-problem_account | F5: report-problem_account | G5: =TRUE() -> TRUE
A6: Looking for help with report problem account. | B6: agent | C6: agent | D6: =TRUE() -> TRUE | E6: report-problem_account | F6: report-problem_account | G6: =TRUE() -> TRUE
A7: Calling regarding report problem account. | B7: agent | C7: agent | D7: =TRUE() -> TRUE | E7: report-problem_account | F7: report-problem_account | G7: =TRUE() -> TRUE
A8: Need assistance with report problem account. | B8: agent | C8: agent | D8: =TRUE() -> TRUE | E8: report-problem_account | F8: report-problem_account | G8: =TRUE() -> TRUE
A9: I want information about report problem account. | B9: agent | C9: agent | D9: =TRUE() -> TRUE | E9: report-problem_account | F9: report-problem_account | G9: =TRUE() -> TRUE
A10: Help with report problem account. | B10: agent | C10: agent | D10: =TRUE() -> TRUE | E10: report-problem_account | F10: report-problem_account | G10: =TRUE() -> TRUE
A11: Question about report problem account. | B11: agent | C11: agent | D11: =TRUE() -> TRUE | E11: report-problem_account | F11: report-problem_account | G11: =TRUE() -> TRUE
A12: I'm calling about report problem account. | B12: agent | C12: agent | D12: =TRUE() -> TRUE | E12: report-problem_account | F12: report-problem_account | G12: =TRUE() -> TRUE
A13: I'd like information on report problem account. | B13: agent | C13: agent | D13: =TRUE() -> TRUE | E13: report-problem_account | F13: report-problem_account | G13: =TRUE() -> TRUE
... A61: I'd appreciate help with report problem account. | B61: agent | C61: agent | D61: =TRUE() -> TRUE | E61: report-problem_account | F61: report-problem_account | G61: =TRUE() -> TRUE
A62: HEAD INTENT ACCURACY | D62: 100.0%
A63: SUB INTENT ACCURACY | G63: 100.0%

Sheet AG_request-address
A1: utterance | B1: expected_head_intent | C1: detected_head_intent | D1: head_intent_match | E1: expected_sub_intent | F1: detected_sub_intent | G1: sub_intent_match | H1: error
A2: Request address | B2: agent | C2: agent | D2: =TRUE() -> TRUE | E2: request-address | F2: request-address | G2: =TRUE() -> TRUE
A3: I need help with request address. | B3: agent | C3: agent | D3: =TRUE() -> TRUE | E3: request-address | F3: request-address | G3: =TRUE() -> TRUE
A4: Calling about request address. | B4: agent | C4: agent | D4: =TRUE() -> TRUE | E4: request-address | F4: request-address | G4: =TRUE() -> TRUE
A5: I have a question about request address. | B5: agent | C5: agent | D5: =TRUE() -> TRUE | E5: request-address | F5: request-address | G5: =TRUE() -> TRUE
A6: Looking for help with request address. | B6: agent | C6: agent | D6: =TRUE() -> TRUE | E6: request-address | F6: request-address | G6: =TRUE() -> TRUE
A7: Calling regarding request address. | B7: agent | C7: agent | D7: =TRUE() -> TRUE | E7: request-address | F7: request-address | G7: =TRUE() -> TRUE
A8: Need assistance with request address. | B8: agent | C8: agent | D8: =TRUE() -> TRUE | E8: request-address | F8: request-address | G8: =TRUE() -> TRUE
A9: I want information about request address. | B9: agent | C9: agent | D9: =TRUE() -> TRUE | E9: request-address | F9: request-address | G9: =TRUE() -> TRUE
A10: Help with request address. | B10: agent | C10: agent | D10: =TRUE() -> TRUE | E10: request-address | F10: request-address | G10: =TRUE() -> TRUE
A11: Question about request address. | B11: agent | D11: =FALSE() -> FALSE | E11: request-address | G11: =FALSE() -> FALSE
A12: I'm calling about request address. | B12: agent | C12: agent | D12: =TRUE() -> TRUE | E12: request-address | F12: request-address | G12: =TRUE() -> TRUE
A13: I'd like information on request address. | B13: agent | C13: agent | D13: =TRUE() -> TRUE | E13: request-address | F13: request-address | G13: =TRUE() -> TRUE
A14: I need information on request address. | B14: agent | C14: agent | D14: =TRUE() -> TRUE | E14: request-address | F14: request-address | G14: =TRUE() -> TRUE
A15: Can you help me with request address? | B15: agent | C15: agent | D15: =TRUE() -> TRUE | E15: request-address | F15: request-address | G15: =TRUE() -> TRUE
A16: I wanted to ask about request address. | B16: agent | C16: agent | D16: =TRUE() -> TRUE | E16: request-address | F16: request-address | G16: =TRUE() -> TRUE
A17: This is regarding request address. | B17: agent | D17: =FALSE() -> FALSE | E17: request-address | G17: =FALSE() -> FALSE
A18: I'm calling regarding request address. | B18: agent | C18: agent | D18: =TRUE() -> TRUE | E18: request-address | F18: request-address | G18: =TRUE() -> TRUE
A19: I have a question regarding request address. | B19: agent | C19: agent | D19: =TRUE() -> TRUE | E19: request-address | F19: request-address | G19: =TRUE() -> TRUE
A20: Could you help me with request address? | B20: agent | C20: agent | D20: =TRUE() -> TRUE | E20: request-address | F20: request-address | G20: =TRUE() -> TRUE
A21: I'm trying to get help with request address. | B21: agent | C21: agent | D21: =TRUE() -> TRUE | E21: request-address | F21: request-address | G21: =TRUE() -> TRUE
A22: I just have a question about request address. | B22: agent | C22: agent | D22: =TRUE() -> TRUE | E22: request-address | F22: request-address | G22: =TRUE() -> TRUE
A23: I'm calling to ask about request address. | B23: agent | C23: agent | D23: =TRUE() -> TRUE | E23: request-address | F23: request-address | G23: =TRUE() -> TRUE
A24: Reaching out about request address. | B24: agent | C24: agent | D24: =TRUE() -> TRUE | E24: request-address | F24: request-address | G24: =TRUE() -> TRUE
A25: I'd like to ask about request address. | B25: agent | C25: agent | D25: =TRUE() -> TRUE | E25: request-address | F25: request-address | G25: =TRUE() -> TRUE
A26: Wanted to check on request address. | B26: agent | D26: =FALSE() -> FALSE | E26: request-address | G26: =FALSE() -> FALSE
A27: Hoping to get some help with request address. | B27: agent | C27: agent | D27: =TRUE() -> TRUE | E27: request-address | F27: request-address | G27: =TRUE() -> TRUE
A28: I was hoping you could help me with request address. | B28: agent | C28: agent | D28: =TRUE() -> TRUE | E28: request-address | F28: request-address | G28: =TRUE() -> TRUE
A29: My question is about request address. | B29: agent | C29: agent | D29: =TRUE() -> TRUE | E29: request-address | F29: request-address | G29: =TRUE() -> TRUE
A30: I'm following up about request address. | B30: agent | C30: agent | D30: =TRUE() -> TRUE | E30: request-address | F30: request-address | G30: =TRUE() -> TRUE
A31: I want to talk to someone about request address. | B31: agent | C31: agent | D31: =TRUE() -> TRUE | E31: request-address | F31: request-address | G31: =TRUE() -> TRUE
A32: I have a question about my request address. | B32: agent | C32: agent | D32: =TRUE() -> TRUE | E32: request-address | F32: request-address | G32: =TRUE() -> TRUE
A33: I'm calling about my request address. | B33: agent | C33: agent | D33: =TRUE() -> TRUE | E33: request-address | F33: request-address | G33: =TRUE() -> TRUE
A34: It's about my request address. | B34: agent | C34: agent | D34: =TRUE() -> TRUE | E34: request-address | F34: request-address | G34: =TRUE() -> TRUE
A35: I need help with my request address. | B35: agent | C35: agent | D35: =TRUE() -> TRUE | E35: request-address | F35: request-address | G35: =TRUE() -> TRUE
A36: Can you help me with my request address? | B36: agent | C36: agent | D36: =TRUE() -> TRUE | E36: request-address | F36: request-address | G36: =TRUE() -> TRUE
A37: I have an issue with my request address. | B37: agent | C37: agent | D37: =TRUE() -> TRUE | E37: request-address | F37: request-address | G37: =TRUE() -> TRUE
A38: I have a concern about my request address. | B38: agent | C38: agent | D38: =TRUE() -> TRUE | E38: request-address | F38: request-address | G38: =TRUE() -> TRUE
... A44: I'd like to understand my request address. | B44: agent | C44: agent | D44: =TRUE() -> TRUE | E44: request-address | F44: request-address | G44: =TRUE() -> TRUE
A45: I'm confused about my request address. | B45: agent | C45: agent | D45: =TRUE() -> TRUE | E45: request-address | F45: vague-address | G45: =FALSE() -> FALSE
...

Sheet AG_request-agent
A1: utterance | B1: expected_head_intent | C1: detected_head_intent | D1: head_intent_match | E1: expected_sub_intent | F1: detected_sub_intent | G1: sub_intent_match | H1: error
A2: Request agent | B2: agent | C2: agent | D2: =TRUE() -> TRUE | E2: request-agent | F2: request-agent | G2: =TRUE() -> TRUE
A3: I need help with request agent. | B3: agent | C3: agent | D3: =TRUE() -> TRUE | E3: request-agent | F3: request-agent | G3: =TRUE() -> TRUE
A4: Calling about request agent. | B4: agent | C4: agent | D4: =TRUE() -> TRUE | E4: request-agent | F4: request-agent | G4: =TRUE() -> TRUE
A5: I have a question about request agent. | B5: agent | C5: agent | D5: =TRUE() -> TRUE | E5: request-agent | F5: request-agent | G5: =TRUE() -> TRUE
A6: Looking for help with request agent. | B6: agent | C6: agent | D6: =TRUE() -> TRUE | E6: request-agent | F6: request-agent | G6: =TRUE() -> TRUE
A7: Calling regarding request agent. | B7: agent | C7: agent | D7: =TRUE() -> TRUE | E7: request-agent | F7: request-agent | G7: =TRUE() -> TRUE
A8: Need assistance with request agent. | B8: agent | C8: agent | D8: =TRUE() -> TRUE | E8: request-agent | F8: request-agent | G8: =TRUE() -> TRUE
A9: I want information about request agent. | B9: agent | C9: agent | D9: =TRUE() -> TRUE | E9: request-agent | F9: request-agent | G9: =TRUE() -> TRUE
A10: Help with request agent. | B10: agent | C10: agent | D10: =TRUE() -> TRUE | E10: request-agent | F10: request-agent | G10: =TRUE() -> TRUE
A11: Question about request agent. | B11: agent | C11: agent | D11: =TRUE() -> TRUE | E11: request-agent | F11: request-agent | G11: =TRUE() -> TRUE
A12: I'm calling about request agent. | B12: agent | C12: agent | D12: =TRUE() -> TRUE | E12: request-agent | F12: request-agent | G12: =TRUE() -> TRUE
A13: I'd like information on request agent. | B13: agent | C13: agent | D13: =TRUE() -> TRUE | E13: request-agent | F13: request-agent | G13: =TRUE() -> TRUE
... A40: I need to ask about my request agent. | B40: agent | C40: agent | D40: =TRUE() -> TRUE | E40: request-agent | F40: request-agent | G40: =TRUE() -> TRUE
A41: Wanted to check on my request agent. | B41: agent | D41: =FALSE() -> FALSE | E41: request-agent | G41: =FALSE() -> FALSE
A42: I'm following up on my request agent. | B42: agent | C42: agent | D42: =TRUE() -> TRUE | E42: request-agent | F42: request-agent | G42: =TRUE() -> TRUE
A43: Question about my request agent. | B43: agent | C43: agent | D43: =TRUE() -> TRUE | E43: request-agent | F43: request-agent | G43: =TRUE() -> TRUE
A44: I'd like to understand my request agent. | B44: agent | C44: agent | D44: =TRUE() -> TRUE | E44: request-agent | F44: request-agent | G44: =TRUE() -> TRUE
A45: I'm confused about my request agent. | B45: agent | C45: agent | D45: =TRUE() -> TRUE | E45: request-agent | F45: request-agent | G45: =TRUE() -> TRUE
A46: I have a quick question about my request agent. | B46: agent | C46: agent | D46: =TRUE() -> TRUE | E46: request-agent | F46: request-agent | G46: =TRUE() -> TRUE
A47: Need to take care of my request agent. | B47: agent | C47: agent | D47: =TRUE() -> TRUE | E47: request-agent | F47: request-agent | G47: =TRUE() -> TRUE
A48: Calling about my request agent today. | B48: agent | C48: agent | D48: =TRUE() -> TRUE | E48: request-agent | F48: request-agent | G48: =TRUE() -> TRUE
A49: Yeah, I have a question about request agent. | B49: agent | C49: agent | D49: =TRUE() -> TRUE | E49: request-agent | F49: request-agent | G49: =TRUE() -> TRUE
A50: Hi, I'm calling about request agent. | B50: agent | C50: agent | D50: =TRUE() -> TRUE | E50: request-agent | F50: request-agent | G50: =TRUE() -> TRUE
A51: So I need some help with request agent. | B51: agent | C51: agent | D51: =TRUE() -> TRUE | E51: request-agent | F51: request-agent | G51: =TRUE() -> TRUE
A52: Okay, I have a question about request agent. | B52: agent | C52: agent | D52: =TRUE() -> TRUE | E52: request-agent | F52: request-agent | G52: =TRUE() -> TRUE
A53: Hello, I wanted to ask about request agent. | B53: agent | C53: agent | D53: =TRUE() -> TRUE | E53: request-agent | F53: request-agent | G53: =TRUE() -> TRUE
... A61: I'd appreciate help with request agent. | B61: agent | C61: agent | D61: =TRUE() -> TRUE | E61: request-agent | F61: request-agent | G61: =TRUE() -> TRUE
A62: HEAD INTENT ACCURACY | D62: 98.33%
A63: SUB INTENT ACCURACY | G63: 98.33%

Sheet AG_request-agent_specific
A1: utterance | B1: expected_head_intent | C1: detected_head_intent | D1: head_intent_match | E1: expected_sub_intent | F1: detected_sub_intent | G1: sub_intent_match | H1: error
A2: Request agent specific | B2: agent | C2: agent | D2: =TRUE() -> TRUE | E2: request-agent_specific | F2: request-agent_specific | G2: =TRUE() -> TRUE
A3: I need help with request agent specific. | B3: agent | C3: agent | D3: =TRUE() -> TRUE | E3: request-agent_specific | F3: request-agent_specific | G3: =TRUE() -> TRUE
A4: Calling about request agent specific. | B4: agent | C4: agent | D4: =TRUE() -> TRUE | E4: request-agent_specific | F4: request-agent_specific | G4: =TRUE() -> TRUE
A5: I have a question about request agent specific. | B5: agent | C5: agent | D5: =TRUE() -> TRUE | E5: request-agent_specific | F5: request-agent_specific | G5: =TRUE() -> TRUE
A6: Looking for help with request agent specific. | B6: agent | C6: agent | D6: =TRUE() -> TRUE | E6: request-agent_specific | F6: request-agent_specific | G6: =TRUE() -> TRUE
A7: Calling regarding request agent specific. | B7: agent | C7: agent | D7: =TRUE() -> TRUE | E7: request-agent_specific | F7: request-agent_specific | G7: =TRUE() -> TRUE
A8: Need assistance with request agent specific. | B8: agent | C8: agent | D8: =TRUE() -> TRUE | E8: request-agent_specific | F8: request-agent_specific | G8: =TRUE() -> TRUE
A9: I want information about request agent specific. | B9: agent | C9: agent | D9: =TRUE() -> TRUE | E9: request-agent_specific | F9: request-agent_specific | G9: =TRUE() -> TRUE
A10: Help with request agent specific. | B10: agent | C10: agent | D10: =TRUE() -> TRUE | E10: request-agent_specific | F10: request-agent_specific | G10: =TRUE() -> TRUE
A11: Question about request agent specific. | B11: agent | C11: agent | D11: =TRUE() -> TRUE | E11: request-agent_specific | F11: request-agent_specific | G11: =TRUE() -> TRUE
A12: I'm calling about request agent specific. | B12: agent | C12: agent | D12: =TRUE() -> TRUE | E12: request-agent_specific | F12: request-agent_specific | G12: =TRUE() -> TRUE
A13: I'd like information on request agent specific. | B13: agent | C13: agent | D13: =TRUE() -> TRUE | E13: request-agent_specific | F13: request-agent_specific | G13: =TRUE() -> TRUE
... A33: I'm calling about my request agent specific. | B33: agent | C33: agent | D33: =TRUE() -> TRUE | E33: request-agent_specific | F33: request-agent_specific | G33: =TRUE() -> TRUE
A34: It's about my request agent specific. | B34: agent | D34: =FALSE() -> FALSE | E34: request-agent_specific | G34: =FALSE() -> FALSE
A35: I need help with my request agent specific. | B35: agent | C35: agent | D35: =TRUE() -> TRUE | E35: request-agent_specific | F35: request-agent_specific | G35: =TRUE() -> TRUE
A36: Can you help me with my request agent specific? | B36: agent | C36: agent | D36: =TRUE() -> TRUE | E36: request-agent_specific | F36: request-agent_specific | G36: =TRUE() -> TRUE
A37: I have an issue with my request agent specific. | B37: agent | C37: agent | D37: =TRUE() -> TRUE | E37: request-agent_specific | F37: request-agent_specific | G37: =TRUE() -> TRUE
A38: I have a concern about my request agent specific. | B38: agent | C38: agent | D38: =TRUE() -> TRUE | E38: request-agent_specific | F38: request-agent_specific | G38: =TRUE() -> TRUE
